2022-05-30 15:09:18,057 ERROR: Exception on /edit_profile [POST] [in D:\python\МегаУчебник\microblog\venv\lib\site-packages\flask\app.py:1455]
Traceback (most recent call last):
  File "D:\python\МегаУчебник\microblog\venv\lib\site-packages\sqlalchemy\engine\base.py", line 1819, in _execute_context
    self.dialect.do_execute(
  File "D:\python\МегаУчебник\microblog\venv\lib\site-packages\sqlalchemy\engine\default.py", line 732, in do_execute
    cursor.execute(statement, parameters)
sqlite3.IntegrityError: UNIQUE constraint failed: user.username

The above exception was the direct cause of the following exception:

Traceback (most recent call last):
  File "D:\python\МегаУчебник\microblog\venv\lib\site-packages\flask\app.py", line 2077, in wsgi_app
    response = self.full_dispatch_request()
  File "D:\python\МегаУчебник\microblog\venv\lib\site-packages\flask\app.py", line 1525, in full_dispatch_request
    rv = self.handle_user_exception(e)
  File "D:\python\МегаУчебник\microblog\venv\lib\site-packages\flask\app.py", line 1523, in full_dispatch_request
    rv = self.dispatch_request()
  File "D:\python\МегаУчебник\microblog\venv\lib\site-packages\flask\app.py", line 1509, in dispatch_request
    return self.ensure_sync(self.view_functions[rule.endpoint])(**req.view_args)
  File "D:\python\МегаУчебник\microblog\venv\lib\site-packages\flask_login\utils.py", line 303, in decorated_view
    return current_app.ensure_sync(func)(*args, **kwargs)
  File "D:\python\МегаУчебник\microblog\app\routes.py", line 86, in edit_profile
    db.session.commit()
  File "<string>", line 2, in commit
  File "D:\python\МегаУчебник\microblog\venv\lib\site-packages\sqlalchemy\orm\session.py", line 1435, in commit
    self._transaction.commit(_to_root=self.future)
  File "D:\python\МегаУчебник\microblog\venv\lib\site-packages\sqlalchemy\orm\session.py", line 829, in commit
    self._prepare_impl()
  File "D:\python\МегаУчебник\microblog\venv\lib\site-packages\sqlalchemy\orm\session.py", line 808, in _prepare_impl
    self.session.flush()
  File "D:\python\МегаУчебник\microblog\venv\lib\site-packages\sqlalchemy\orm\session.py", line 3367, in flush
    self._flush(objects)
  File "D:\python\МегаУчебник\microblog\venv\lib\site-packages\sqlalchemy\orm\session.py", line 3506, in _flush
    with util.safe_reraise():
  File "D:\python\МегаУчебник\microblog\venv\lib\site-packages\sqlalchemy\util\langhelpers.py", line 70, in __exit__
    compat.raise_(
  File "D:\python\МегаУчебник\microblog\venv\lib\site-packages\sqlalchemy\util\compat.py", line 207, in raise_
    raise exception
  File "D:\python\МегаУчебник\microblog\venv\lib\site-packages\sqlalchemy\orm\session.py", line 3467, in _flush
    flush_context.execute()
  File "D:\python\МегаУчебник\microblog\venv\lib\site-packages\sqlalchemy\orm\unitofwork.py", line 456, in execute
    rec.execute(self)
  File "D:\python\МегаУчебник\microblog\venv\lib\site-packages\sqlalchemy\orm\unitofwork.py", line 630, in execute
    util.preloaded.orm_persistence.save_obj(
  File "D:\python\МегаУчебник\microblog\venv\lib\site-packages\sqlalchemy\orm\persistence.py", line 237, in save_obj
    _emit_update_statements(
  File "D:\python\МегаУчебник\microblog\venv\lib\site-packages\sqlalchemy\orm\persistence.py", line 1001, in _emit_update_statements
    c = connection._execute_20(
  File "D:\python\МегаУчебник\microblog\venv\lib\site-packages\sqlalchemy\engine\base.py", line 1631, in _execute_20
    return meth(self, args_10style, kwargs_10style, execution_options)
  File "D:\python\МегаУчебник\microblog\venv\lib\site-packages\sqlalchemy\sql\elements.py", line 325, in _execute_on_connection
    return connection._execute_clauseelement(
  File "D:\python\МегаУчебник\microblog\venv\lib\site-packages\sqlalchemy\engine\base.py", line 1498, in _execute_clauseelement
    ret = self._execute_context(
  File "D:\python\МегаУчебник\microblog\venv\lib\site-packages\sqlalchemy\engine\base.py", line 1862, in _execute_context
    self._handle_dbapi_exception(
  File "D:\python\МегаУчебник\microblog\venv\lib\site-packages\sqlalchemy\engine\base.py", line 2043, in _handle_dbapi_exception
    util.raise_(
  File "D:\python\МегаУчебник\microblog\venv\lib\site-packages\sqlalchemy\util\compat.py", line 207, in raise_
    raise exception
  File "D:\python\МегаУчебник\microblog\venv\lib\site-packages\sqlalchemy\engine\base.py", line 1819, in _execute_context
    self.dialect.do_execute(
  File "D:\python\МегаУчебник\microblog\venv\lib\site-packages\sqlalchemy\engine\default.py", line 732, in do_execute
    cursor.execute(statement, parameters)
sqlalchemy.exc.IntegrityError: (sqlite3.IntegrityError) UNIQUE constraint failed: user.username
[SQL: UPDATE user SET username=?, about_me=? WHERE user.id = ?]
[parameters: ('Susan', '', 2)]
(Background on this error at: https://sqlalche.me/e/14/gkpj)
2022-05-30 15:09:46,651 INFO: Microblog startup [in D:\python\МегаУчебник\microblog\app\__init__.py:40]
2022-05-30 15:09:53,994 ERROR: Exception on /edit_profile [GET] [in D:\python\МегаУчебник\microblog\venv\lib\site-packages\flask\app.py:1455]
Traceback (most recent call last):
  File "D:\python\МегаУчебник\microblog\venv\lib\site-packages\flask\app.py", line 2077, in wsgi_app
    response = self.full_dispatch_request()
  File "D:\python\МегаУчебник\microblog\venv\lib\site-packages\flask\app.py", line 1525, in full_dispatch_request
    rv = self.handle_user_exception(e)
  File "D:\python\МегаУчебник\microblog\venv\lib\site-packages\flask\app.py", line 1523, in full_dispatch_request
    rv = self.dispatch_request()
  File "D:\python\МегаУчебник\microblog\venv\lib\site-packages\flask\app.py", line 1509, in dispatch_request
    return self.ensure_sync(self.view_functions[rule.endpoint])(**req.view_args)
  File "D:\python\МегаУчебник\microblog\venv\lib\site-packages\flask_login\utils.py", line 303, in decorated_view
    return current_app.ensure_sync(func)(*args, **kwargs)
  File "D:\python\МегаУчебник\microblog\app\routes.py", line 82, in edit_profile
    form= EditProfileForm(current_user.username)
  File "D:\python\МегаУчебник\microblog\venv\lib\site-packages\wtforms\form.py", line 208, in __call__
    return type.__call__(cls, *args, **kwargs)
  File "D:\python\МегаУчебник\microblog\app\forms.py", line 36, in __init__
    super(EditPrifileForm, self).__init__(*args, **kwargs)
NameError: name 'EditPrifileForm' is not defined
2022-05-30 15:10:34,148 INFO: Microblog startup [in D:\python\МегаУчебник\microblog\app\__init__.py:40]
2022-05-30 15:29:16,296 INFO: Microblog startup [in D:\python\МегаУчебник\microblog\app\__init__.py:40]
2022-05-30 15:29:32,777 INFO: Microblog startup [in D:\python\МегаУчебник\microblog\app\__init__.py:40]
